Workbook
Name f: #REF!
Name GruppeA_farve: #REF!
Name GruppeB_farve: #REF!

Sheet Forside
A1: Kriterium navn | B1: Kriterium forkortelse | C1: Kriterium vægtning (0-5) | D1: Samlet kriterium score
A2: Klimaforandringer | B2: =Matrix!A2 -> E1 | C2: =ROUNDDOWN(AVERAGE(DVA!B2:C2),0) -> 1 | D2: =Matrix!G2 -> 100
A3: Forurening | B3: =Matrix!A26 -> E2 | C3: =ROUNDDOWN(AVERAGE(DVA!B3:C3),0) -> 0 | D3: =Matrix!G26 -> 100
A4: Vand- og havressourcer | B4: =Matrix!A51 -> E3 | C4: =ROUNDDOWN(AVERAGE(DVA!B4:C4),0) -> 1 | D4: =Matrix!G51 -> 100
A5: Biodiversitet og økosystemer | B5: =Matrix!A57 -> E4 | C5: =ROUNDDOWN(AVERAGE(DVA!B5:C5),0) -> 2 | D5: =Matrix!G57 -> 0
A6: Ressourceanvendelse og cirkulær økonomi | B6: =Matrix!A70 -> E5 | C6: =ROUNDDOWN(AVERAGE(DVA!B6:C6),0) -> 4 | D6: =Matrix!G70 -> 0
A7: Egen arbejdsstyrke | B7: =Matrix!A81 -> S1 | C7: =ROUNDDOWN(AVERAGE(DVA!B7:C7),0) -> 3 | D7: =Matrix!G81 -> 65
A8: Arbejdstagere i værdikæden | B8: =Matrix!A109 -> S2 | C8: =ROUNDDOWN(AVERAGE(DVA!B8:C8),0) -> 3 | D8: =Matrix!G109 -> 45
A9: Berørte samfund | B9: =Matrix!A124 -> S3 | C9: =ROUNDDOWN(AVERAGE(DVA!B9:C9),0) -> 3 | D9: =Matrix!G124 -> 100
A10: Forbrugere og slutbrugere | B10: =Matrix!A133 -> S4 | C10: =ROUNDDOWN(AVERAGE(DVA!B10:C10),0) -> 4 | D10: =Matrix!G133 -> 70
A11: God forretningsskik | B11: =Matrix!A142 -> G1 | C11: =ROUNDDOWN(AVERAGE(DVA!B11:C11),0) -> 2 | D11: =Matrix!G142 -> 70
A12: Samlet score | B12: =SUM(Matrix!I2,Matrix!I26,Matrix!I51,Matrix!I57,Matrix!I70,Matrix!I81,Matrix!I109,Matrix!I124,Matrix!I133,Matrix!I142) -> 52
A14: Virksomhedsnavn | B14: Djurs Consult
A15: Lokation | B15: Hovedkontor
A16: Adresse | B16: Østergade 7, 8963 Auning
A17: Antal ansatte | B17: 23
A18: Årlig omsætning/noget andet | B18: 10000000
A19: Branchekode | B19: 71.12.10 Rådgivende ingeniøraktiviteter inden for byggeri og anlægsarbejder

Sheet DVA_Spørgsmål
B1: Spørgsmål | C1: Ja | D1: Nej | E1: Beskrivelse | F1: Typiske brancher
A2: E1 | B2: Klimaforandringer
A3: Impact | B3: Udleder virksomheden direkte drivhusgasser (CO₂e) i forbindelse med drift, transport eller energiforbrug? | C3: TRUE | D3: FALSE | E3: Gælder hvis virksomheden fx bruger firmabiler, har produktionsudstyr, opvarmer lokaler med olie/gas, eller flyver på firmarejser. Kontorarbejde uden transport tæller ikke. | F3: Transport, byggeri, produktion, landbrug, detail med transport
B4: Forårsager virksomhedens produkter, ydelser eller drift væsentlig indirekte CO₂e-udledning i værdikæden? | C4: TRUE | D4: FALSE | E4: Gælder fx salg af fysiske varer, rådgivning om CO₂-intensive projekter, eller outsourcing af produktion. Kun meget simple servicefag (massør, frisør osv.) undgår dette. | F4: Produktion, engros, rådgivning, detailhandel, byggeri
B5: Tilbyder virksomheden produkter eller ydelser, der kan hjælpe andre med at reducere deres klimaaftryk? | C5: FALSE | D5: TRUE | E5: Gælder fx energirådgivning, klimateknologier, software til måling af emissioner eller klimavenlige produkter. Gælder også ansvar i værdikæden. | F5: Cleantech, konsulenter, energi, grøn transport, IT-software
B6: Er virksomheden aktiv i en branche, der ifølge EU eller Klimarådet er blandt de mest CO₂e-intensive? | C6: FALSE | D6: FALSE | E6: Gælder kun hvis virksomheden er i en af følgende brancher: energi, byggeri, cement, stål, landbrug, transport, minedrift, kemi, plastproduktion, tekstil eller shipping. | F6: Energi, byggeri, cement, stål, landbrug, transport, minedrift, kemi, plastproduktion, tekstil, shipping (liste kan justeres efter national/EU-kilder).
B7: Har virksomheden indvoldveret i aktiviteter, der medfører ændringer i arealanvendelse med betydning for klimaet? | C7: FALSE | D7: TRUE | E7: Gælder fx byggeri, skovrydning, anlægsarbejde, eller store parkeringspladser, som fjerner grønne arealer og påvirker kulstofbinding. | F7: Byggeri, anlæg, landbrug, minedrift, logistikcentre
A8: Finansiel | B8: Kan klimaforandringer medføre betydningsfuldt højere omkostninger for virksomheden (f.eks. energi, forsikring, leverancer)? | C8: TRUE | D8: FALSE | E8: Gælder fx stigende elpriser, forsikringer, transport, eller udgifter til klimatilpasning eller indkøb. | F8: Alle brancher – men især energiintensive
B9: Kan klimarelateret regulering påvirke virksomhedens konkurrenceevne eller krav til produkter? | C9: FALSE | D9: FALSE | E9: Gælder fx CO₂-afgifter, EU's taksonomi, energikrav til bygninger eller dokumentationskrav fra kunder. | F9: Produktion, byggeri, transport, fødevarer, eksport
B10: Har virksomheden drift, hoved- leverandører eller kunder i geografiske områder med risiko for oversvømmelse, tørke eller storme? | C10: FALSE | D10: TRUE | E10: Gælder kun hvis man har produktion, kontor eller nøgleleverandører i områder, som ifølge myndigheder (fx DMI eller EU) er klimarisikozoner. | F10: Landbrug, byggeri, transport, produktion, fødevarer
B11: Kan virksomheden miste eller vinde kunder, investorer eller markedsandele pga. krav om lavt klimaaftryk? | C11: FALSE | D11: FALSE | E11: Gælder hvis virksomheden har kunder, partnere eller investorer, der stiller krav om dokumenteret CO₂-reduktion, klimamærkning eller ESG. | F11: Rådgivning, mode, tech, byggeri, detail, transport, fødevarer
B12: Har virksomheden mulighed for at tjene penge på klimaforandringer (f.eks. via nye markeder, produkter eller ydelser)? | C12: FALSE | D12: FALSE | E12: Gælder fx klimatilpasning, grønne produkter, investeringer i vedvarende energi, eller øget efterspørgsel på rådgivning eller data. | F12: Energi, rådgivning, tech, byggeri, forsyning
A13: E2 | B13: Forurening
A14: Impact | B14: Udleder virksomheden forurenedne stoffer til luft, jord eller vand? | C14: FALSE | D14: TRUE | E14: Gælder direkte udledning fra drift, f.eks. partikler (PM), NOx, SO₂, tungmetaller, næringsstoffer, olie, kemikalier mv. Gælder også udledning fra firmatransport og entreprenørmaskiner, hvis de bruger fossile brændsler og ikke har renseteknologi. Gælder ikke CO₂ eller andre drivhusgasser – de vurderes under E1. | F14: Produktion, industri, byggeri, landbrug, transport, fødevare, varmeværker
B15: Bruger eller producerer virksomheden kemikalier klassificeret som miljøfarlige? | C15: FALSE | D15: TRUE | E15: Omfatter f.eks. PFAS, pesticider, tungmetaller, akvatoksiske stoffer, olier, opløsningsmidler eller kemikalier mærket med miljøfare (GHS09). Almindelige kontorartikler og husholdningsmidler i små mængder tæller ikke. | F15: Kemi, plast, rengøring, landbrug, medicinal, produktion, maling/lak
B16: Håndterer virksomheden processpildevand, farligt affald eller luftfiltrering? | C16: FALSE | D16: TRUE | E16: Dækker hvis virksomheden selv står for behandling, opbevaring eller bortledning af stoffer, der skal håndteres miljømæssigt forsvarligt – fx via renseanlæg, filtre, affaldssortering, beholdere til olie eller kemikalier. | F16: Industri, fødevare, metal, tekstil, affaldsbehandling, vaskerier, byggeri
B17: Skaber virksomhedens aktiviteter målelig støj-, lys- eller lugtforurening i omgivelserne? | C17: TRUE | D17: FALSE | E17: Gælder fx støj fra maskiner, trafik, byggepladser eller events; lysforurening fra natbelysning; lugtgener fra produktion eller affald. Ikke almindelig kontoraktivitet eller internt støjniveau. | F17: Transport, events, restauranter, byggeri, produktion, landbrug
B18: Har virksomheden indflydelse på valg af materialer i produkter eller projekter, hvor miljøskadelige stoffer kan indgå? | C18: FALSE | D18: TRUE | E18: Omfatter hvor virksomheden designer, specificerer eller anbefaler materialer, f.eks. maling, lim, plasttyper eller byggematerialer. Gælder ikke videresalg uden indflydelse på valg. | F18: Arkitekter, ingeniører, designere, konsulenter, entreprenører, byggeri
A19: Finansiel | B19: Påfører virksomhedens udledning til luft, jord eller vand omkostninger eller krav fra myndigheder? | C19: FALSE | D19: TRUE | E19: Ja, hvis der er udledning fra drift (f.eks. partikler, NOx, olie, tungmetaller, kemikalier, næringsstoffer), som kræver tilladelser, kontrol, afgifter, oprensning, eller investering i rense-/filterudstyr. Gælder også udledning fra firmakøretøjer, maskiner eller spildevand. | F19: Produktion, landbrug, byggeri, transport, affald, fødevare, varmeværker
B20: Bruger virksomheden miljøfarlige stoffer, der kan blive ramt af forbud, begrænsninger eller skærpede krav? | C20: FALSE | D20: TRUE | E20: Ja, hvis virksomheden bruger stoffer, der er klassificeret som miljøfarlige (fx PFAS, pesticider, bly, opløsningsmidler, olier, kemikalier mærket GHS09), og disse kan blive begrænset, kræve substitution eller dokumentation. | F20: Kemi, plast, rengøring, medicinal, landbrug, tekstil, produktion, maling
B21: Møder virksomheden kundekrav eller udbudsbetingelser, hvor dokumentation eller begrænsning af forurening er påkrævet? | C21: FALSE | D21: TRUE | E21: Ja, hvis virksomheden skal dokumentere lav forurening (f.eks. miljøvaredeklaration, svanemærkning, REACH, ISO 14001) for at opnå eller fastholde ordrer, certificeringer eller udbud. | F21: Byggeri, eksport, B2B-produktion, rådgivere, møbel, tekstil, fødevare
B22: Tilbyder virksomheden produkter eller ydelser, der reducerer miljøforurening ift. standardløsninger? | C22: FALSE | D22: TRUE | E22: Ja, hvis virksomheden producerer eller sælger løsninger, der beviseligt reducerer forurening (fx lav-emissionsprodukter, kemikaliefri alternativer, filtrering, grøn transport, rådgivning i substitution). Gælder kun hvis dokumentationen foreligger eller kræves af kunder. | F22: Cleantech, affald, teknologi, produktionsudstyr, rådgivning, byggeri
B23: Kan virksomheden opnå tilskud, skattelettelser, mærkning eller grønne indkøbsaftaler som kræver dokumenterbar lav miljøforurening? | C23: FALSE | D23: TRUE | E23: Ja, hvis virksomheden er omfattet af eller kan opnå konkrete økonomiske fordele (tilskud, grønne ordninger, præferencer i udbud), hvor adgang er betinget af dokumenteret lav udledning eller fravær af miljøfarlige stoffer. | F23: Grøn teknologi, eksportvirksomheder, byggeri, cleantech, miljømærkede produkter
A24: E3 | B24: Vand- og havressourcer
A25: Impact | B25: Bruger virksomheden vand i driften ud over almindeligt kontorforbrug (toilet, rengøring, kaffe mv.)? | C25: FALSE | D25: TRUE | E25: Gælder hvis virksomheden bruger vand i produktion, processer, køling, rengøring, landbrug eller anden drift, hvor vandforbruget er væsentligt. Ikke relevant ved almindelig kontoraktivitet. | F25: Produktion, landbrug, energi, fødevare, tekstil, metal, vaskerier
B26: Har virksomheden drift eller forsyning i områder med vandmangel eller risiko for tørke? | C26: FALSE | D26: TRUE | E26: Omfatter egne lokationer og nøgleleverandører i regioner med dokumenteret vandknaphed, f.eks. Sydeuropa, visse dele af Afrika, Asien eller tørkeramte danske egne. | F26: Landbrug, tekstil, eksport, fødevare, byggeri
B27: Udleder virksomheden stoffer eller affald til havet, eller har aktiviteter til søs eller i kystnære områder? | C27: FALSE | D27: TRUE | E27: Gælder f.eks. udledning fra rensningsanlæg, transport til søs, offshoreaktiviteter eller affaldshåndtering i havmiljøet. Inkluderer også erosion eller forstyrrelse af kystzoner. | F27: Skibsfart, offshore, affald, byggeri, turisme, akvakultur
B28: Er virksomheden aktiv i fiskeri, havbrug eller udnyttelse af marine ressourcer (fisk, skaldyr, tang mv.)? | C28: TRUE | D28: FALSE | E28: Gælder kommercielt fiskeri, akvakultur, tangproduktion eller tilsvarende aktiviteter, uanset om det er direkte eller via underleverandører. | F28: Fiskeri, akvakultur, fødevarer, eksport
B29: Kan virksomhedens aktiviteter forurene vandmiljøet, f.eks. via kemikalier, affald, gødning eller pesticider? | C29: FALSE | D29: TRUE | E29: Omfatter aktiviteter der kan føre til udledning eller afstrømning af miljøfarlige stoffer til vandløb, grundvand eller havmiljø. Gælder også indirekte påvirkning gennem leverandører. | F29: Landbrug, byggeri, kemi, rengøring, produktion, tekstil
A30: Finansiel | B30: Er virksomhedens drift afhængig af adgang til vand i tilstrækkelig mængde og kvalitet? | C30: FALSE | D30: TRUE | E30: Gælder hvor vand er nødvendigt for driften – f.eks. i produktion, rengøring, køling, vanding eller ingredienser. Også relevant hvis forurening eller knaphed kan forstyrre produktionen. | F30: Produktion, landbrug, vaskerier, fødevarer, kemi
B31: Kan vandkvalitet eller forurening påvirke virksomhedens produkter, råvarer eller processer? | C31: TRUE | D31: FALSE | E31: Gælder f.eks. hvis produktkvalitet afhænger af rent vand (fødevarer, tekstiler), eller hvis råvarer bliver forurenet ved kontakt med vand. | F31: Fødevarer, tekstil, kemi, energi, metal
B32: Kan krav til vandforbrug eller spildevandshåndtering påvirke virksomhedens driftsomkostninger? | C32: FALSE | D32: TRUE | E32: Omfatter f.eks. spildevandsafgifter, investeringskrav i renseudstyr, målere, påbud, certificeringer eller miljøgodkendelser. | F32: Produktion, industri, landbrug, fødevare, byggeri
B33: Er virksomheden eller dens infrastruktur i risiko for havrelaterede klimaeffekter (oversvømmelse, stormflod, havspejl)? | C33: FALSE | D33: FALSE | E33: Gælder hvis lokationer, veje, leverandører eller anden kritisk drift er i lavtliggende eller kystnære områder med risiko for havstigning eller stormskader. | F33: Kystnær industri, havne, logistik, turisme, ejendomme
B34: Kan adgang til hav- eller vandressourcer blive begrænset af udtømning eller regulering og påvirke virksomhedens forsyning? | C34: FALSE | D34: TRUE | E34: Gælder hvis virksomheden er afhængig af ressourcer som fisk, sand, ferskvand, salt eller råstoffer fra havet, og disse kan blive begrænset af myndigheder eller miljøforhold. | F34: Fiskeri, byggeri, kemi, tekstil, fødevarer, eksport
A35: E4 | B35: Biodiversitet og økosystemer
A36: Impact | B36: Påvirker eller ændrer virksomheden arealer direkte gennem byggeri, produktion, landbrug mv. – eller indirekte gennem indflydelse på andres arealanvendelse? | C36: TRUE | D36: FALSE | E36: Dette gælder hvis virksomheden bygger nyt, anlægger infrastruktur, driver landbrug, skovbrug, råstofudvinding eller har indflydelse på andres arealanvendelse (f.eks. gennem rådgivning, investering eller produktkrav). Gælder også hvis virksomheden ejer grunde eller bygninger med betydelig udstrækning eller planlægger nybyggeri. | F36: Byggeri, landbrug, råstofudvinding, skovbrug, transport, ejendomsudvikling, rådgivning
B37: Bruger, sælger eller specificerer virksomheden naturressourcer som træ, fisk, sand, jord, grus eller landbrugsprodukter – direkte eller gennem værdikæden? | C37: FALSE | D37: TRUE | E37: Dækker fx brug, indkøb eller salg af materialer, fødevarer eller råvarer, der stammer fra naturen – f.eks. træ, fisk, mineraler, sand, grus, vand, jord eller landbrugsvarer. Gælder også hvis virksomheden indgår i værdikæder, hvor sådanne ressourcer udvindes. | F37: Landbrug, fødevare, byggeri, tekstil, handel, produktion, engros
B38: Har virksomhedens aktiviteter udledning eller påvirkning, som kan forringe naturen – f.eks. støj, lys, luftforurening eller udslip til jord og vand? | C38: TRUE | D38: FALSE | E38: Omfatter udledning af stoffer (f.eks. pesticider, næringsstoffer, kemikalier) eller forurening med støj, lys eller lugt, der påvirker dyreliv eller naturens balance. Gælder både direkte drift og transport, men ikke almindelig kontordrift. | F38: Byggeri, produktion, transport, events, landbrug, affald
B39: Håndterer, forarbejder eller sælger virksomheden produkter, der stammer fra levende organismer – f.eks. træ, planter, fødevarer eller dyr? | C39: TRUE | D39: FALSE | E39: Gælder hvis virksomheden beskæftiger sig med biologiske materialer – herunder fødevarer, trævarer, landbrugsprodukter, frø, blomster, husdyr eller fisk. | F39: Landbrug, fødevare, handel, træindustri, medicinal, detail
B40: Er der risiko for, at virksomhedens aktiviteter (f.eks. import, transport, jordarbejde) kan sprede invasive arter eller sygdomme i naturen? | C40: FALSE | D40: TRUE | E40: Omfatter risiko for spredning af arter eller sygdomme via transport, import, jordflytning, planter, dyr, emballage eller maskiner – også indirekte gennem leverandører eller kunder. | F40: Byggeri, transport, handel med planter/dyr, import, affald
...

Sheet DVA
B1: impact | C1: Finansiel
A2: E1 | B2: =COUNTIF(DVA_Spørgsmål!C3:C7,TRUE) -> 2 | C2: =COUNTIF(DVA_Spørgsmål!C8:C12,TRUE) -> 1 | E2: Finansiel væsentlighed | F2: Meget høj | G2: {=_xlfn.TEXTJOIN(" ", TRUE, _xlfn._xlws.FILTER($A$2:$A$11, ($B$2:$B$11=0)*($C$2:$C$11=5),""))} | H2: {=_xlfn.TEXTJOIN(" ", TRUE, _xlfn._xlws.FILTER($A$2:$A$11, ($B$2:$B$11=1)*($C$2:$C$11=5),""))} | I2: {=_xlfn.TEXTJOIN(" ", TRUE, _xlfn._xlws.FILTER($A$2:$A$11, ($B$2:$B$11=2)*($C$2:$C$11=5),""))} | J2: {=_xlfn.TEXTJOIN(" ", TRUE, _xlfn._xlws.FILTER($A$2:$A$11, ($B$2:$B$11=3)*($C$2:$C$11=5),""))} | K2: {=_xlfn.TEXTJOIN(" ", TRUE, _xlfn._xlws.FILTER($A$2:$A$11, ($B$2:$B$11=4)*($C$2:$C$11=5),""))} | L2: {=_xlfn.TEXTJOIN(" ", TRUE, _xlfn._xlws.FILTER($A$2:$A$11, ($B$2:$B$11=5)*($C$2:$C$11=5),""))}
A3: E2 | B3: =COUNTIF(DVA_Spørgsmål!C14:C18,TRUE) -> 1 | C3: =COUNTIF(DVA_Spørgsmål!C19:C23,TRUE) -> 0 | F3: Høj | G3: {=_xlfn.TEXTJOIN(" ", TRUE, _xlfn._xlws.FILTER($A$2:$A$11, ($B$2:$B$11=0)*($C$2:$C$11=4),""))} | H3: {=_xlfn.TEXTJOIN(" ", TRUE, _xlfn._xlws.FILTER($A$2:$A$11, ($B$2:$B$11=1)*($C$2:$C$11=4),""))} | I3: {=_xlfn.TEXTJOIN(" ", TRUE, _xlfn._xlws.FILTER($A$2:$A$11, ($B$2:$B$11=2)*($C$2:$C$11=4),""))} | J3: {=_xlfn.TEXTJOIN(" ", TRUE, _xlfn._xlws.FILTER($A$2:$A$11, ($B$2:$B$11=3)*($C$2:$C$11=4),""))} | K3: {=_xlfn.TEXTJOIN(" ", TRUE, _xlfn._xlws.FILTER($A$2:$A$11, ($B$2:$B$11=4)*($C$2:$C$11=4),""))} -> S4 | L3: {=_xlfn.TEXTJOIN(" ", TRUE, _xlfn._xlws.FILTER($A$2:$A$11, ($B$2:$B$11=5)*($C$2:$C$11=4),""))}
A4: E3 | B4: =COUNTIF(DVA_Spørgsmål!C25:C29,TRUE) -> 1 | C4: =COUNTIF(DVA_Spørgsmål!C30:C34,TRUE) -> 1 | F4: Moderat | G4: {=_xlfn.TEXTJOIN(" ", TRUE, _xlfn._xlws.FILTER($A$2:$A$11, ($B$2:$B$11=0)*($C$2:$C$11=3),""))} | H4: {=_xlfn.TEXTJOIN(" ", TRUE, _xlfn._xlws.FILTER($A$2:$A$11, ($B$2:$B$11=1)*($C$2:$C$11=3),""))} | I4: {=_xlfn.TEXTJOIN(" ", TRUE, _xlfn._xlws.FILTER($A$2:$A$11, ($B$2:$B$11=2)*($C$2:$C$11=3),""))} | J4: {=_xlfn.TEXTJOIN(" ", TRUE, _xlfn._xlws.FILTER($A$2:$A$11, ($B$2:$B$11=3)*($C$2:$C$11=3),""))} -> S3 | K4: {=_xlfn.TEXTJOIN(" ", TRUE, _xlfn._xlws.FILTER($A$2:$A$11, ($B$2:$B$11=4)*($C$2:$C$11=3),""))} -> S1 | L4: {=_xlfn.TEXTJOIN(" ", TRUE, _xlfn._xlws.FILTER($A$2:$A$11, ($B$2:$B$11=5)*($C$2:$C$11=3),""))} -> E5
A5: E4 | B5: =COUNTIF(DVA_Spørgsmål!C36:C40,TRUE) -> 3 | C5: =COUNTIF(DVA_Spørgsmål!C41:C45,TRUE) -> 1 | F5: Middel | G5: {=_xlfn.TEXTJOIN(" ", TRUE, _xlfn._xlws.FILTER($A$2:$A$11, ($B$2:$B$11=0)*($C$2:$C$11=2),""))} | H5: {=_xlfn.TEXTJOIN(" ", TRUE, _xlfn._xlws.FILTER($A$2:$A$11, ($B$2:$B$11=1)*($C$2:$C$11=2),""))} | I5: {=_xlfn.TEXTJOIN(" ", TRUE, _xlfn._xlws.FILTER($A$2:$A$11, ($B$2:$B$11=2)*($C$2:$C$11=2),""))} | J5: {=_xlfn.TEXTJOIN(" ", TRUE, _xlfn._xlws.FILTER($A$2:$A$11, ($B$2:$B$11=3)*($C$2:$C$11=2),""))} -> G1 | K5: {=_xlfn.TEXTJOIN(" ", TRUE, _xlfn._xlws.FILTER($A$2:$A$11, ($B$2:$B$11=4)*($C$2:$C$11=2),""))} -> S2 | L5: {=_xlfn.TEXTJOIN(" ", TRUE, _xlfn._xlws.FILTER($A$2:$A$11, ($B$2:$B$11=5)*($C$2:$C$11=2),""))}
A6: E5 | B6: =COUNTIF(DVA_Spørgsmål!C47:C51,TRUE) -> 5 | C6: =COUNTIF(DVA_Spørgsmål!C52:C56,TRUE) -> 3 | F6: Lav | G6: {=_xlfn.TEXTJOIN(" ", TRUE, _xlfn._xlws.FILTER($A$2:$A$11, ($B$2:$B$11=0)*($C$2:$C$11=1),""))} | H6: {=_xlfn.TEXTJOIN(" ", TRUE, _xlfn._xlws.FILTER($A$2:$A$11, ($B$2:$B$11=1)*($C$2:$C$11=1),""))} -> E3 | I6: {=_xlfn.TEXTJOIN(" ", TRUE, _xlfn._xlws.FILTER($A$2:$A$11, ($B$2:$B$11=2)*($C$2:$C$11=1),""))} -> E1 | J6: {=_xlfn.TEXTJOIN(" ", TRUE, _xlfn._xlws.FILTER($A$2:$A$11, ($B$2:$B$11=3)*($C$2:$C$11=1),""))} -> E4 | K6: {=_xlfn.TEXTJOIN(" ", TRUE, _xlfn._xlws.FILTER($A$2:$A$11, ($B$2:$B$11=4)*($C$2:$C$11=1),""))} | L6: {=_xlfn.TEXTJOIN(" ", TRUE, _xlfn._xlws.FILTER($A$2:$A$11, ($B$2:$B$11=5)*($C$2:$C$11=1),""))}
A7: S1 | B7: =COUNTIF(DVA_Spørgsmål!C58:C62,TRUE) -> 4 | C7: =COUNTIF(DVA_Spørgsmål!C63:C67,TRUE) -> 3 | F7: Ikke relevant | G7: {=_xlfn.TEXTJOIN(" ", TRUE, _xlfn._xlws.FILTER($A$2:$A$11, ($B$2:$B$11=0)*($C$2:$C$11=0),""))} | H7: {=_xlfn.TEXTJOIN(" ", TRUE, _xlfn._xlws.FILTER($A$2:$A$11, ($B$2:$B$11=1)*($C$2:$C$11=0),""))} -> E2 | I7: {=_xlfn.TEXTJOIN(" ", TRUE, _xlfn._xlws.FILTER($A$2:$A$11, ($B$2:$B$11=2)*($C$2:$C$11=0),""))} | J7: {=_xlfn.TEXTJOIN(" ", TRUE, _xlfn._xlws.FILTER($A$2:$A$11, ($B$2:$B$11=3)*($C$2:$C$11=0),""))} | K7: {=_xlfn.TEXTJOIN(" ", TRUE, _xlfn._xlws.FILTER($A$2:$A$11, ($B$2:$B$11=4)*($C$2:$C$11=0),""))} | L7: {=_xlfn.TEXTJOIN(" ", TRUE, _xlfn._xlws.FILTER($A$2:$A$11, ($B$2:$B$11=5)*($C$2:$C$11=0),""))}
A8: S2 | B8: =COUNTIF(DVA_Spørgsmål!C69:C73,TRUE) -> 4 | C8: =COUNTIF(DVA_Spørgsmål!C74:C78,TRUE) -> 2 | G8: Ikke relevant | H8: Lav | I8: Middel | J8: Moderat | K8: Høj | L8: Meget høj
A9: S3 | B9: =COUNTIF(DVA_Spørgsmål!C80:C84,TRUE) -> 3 | C9: =COUNTIF(DVA_Spørgsmål!C85:C89,TRUE) -> 3 | G9: Impact væsentlighed
A10: S4 | B10: =COUNTIF(DVA_Spørgsmål!C91:C95,TRUE) -> 4 | C10: =COUNTIF(DVA_Spørgsmål!C96:C100,TRUE) -> 4
A11: G1 | B11: =COUNTIF(DVA_Spørgsmål!C102:C106,TRUE) -> 3 | C11: =COUNTIF(DVA_Spørgsmål!C107:C111,TRUE) -> 2
D29: {=_xlfn.TEXTJOIN(" ",,IF(AND(B2:B11=0,C2:C11=0),A2:A11,E29))}

Sheet Matrix
A1: Kriterium | B1: Indikator | E1: Indikator point | F1: Afkrydsningsfelt | G1: Samlet indikator point | H1: Max Point | I1: Score | J1: Max Score | K1: Gruppevægtning | L1: Hoved-Dokumentation | M1: Kommentarer / Bemærkninger
A2: E1 | B2: Klimaforandringer | G2: =SUM(G4:G25) -> 100 | H2: 100 | I2: =G2*J2/100 -> 5 | J2: =Forside!C2/SUM(Forside!C2:C6)*Matrix!K2*100 -> 5 | K2: 0.4
B3: 1.1 | C3: CO2 udledninger
C4: 1.1.1 | D4: Virksomheden har udregnet og dokumenteret sine CO2e-udledninger for Scope 1 og 2. | E4: 10 | F4: TRUE | G4: =SUMIF(F4:F8,TRUE,E4:E8) -> 35 | H4: 35 | I4: =IF(F4=TRUE,E4*$J$2,0)/100 -> 0.5 | L4: CO2e-beregning opdelt i scope 1 og 2.
C5: 1.1.2 | D5: Virksomheden har udregnet og dokumenteret sine CO2e-udledninger for Scope 1, 2 og 3. | E5: 5 | F5: TRUE | I5: =IF(F5=TRUE,E5*$J$2,0)/100 -> 0.25 | L5: CO2e-beregning opdelt i scope 1, 2 og 3.
C6: 1.1.3 | D6: Virksomheden har en politik for reduktion af sine CO2e-udledninger. | E6: 5 | F6: TRUE | I6: =IF(F6=TRUE,E6*$J$2,0)/100 -> 0.25 | L6: Nedskreven politik.
C7: 1.1.4 | D7: Virksomheden har konkrete mål for reduktion af sine CO2e-udledninger. | E7: 5 | F7: TRUE | I7: =IF(F7=TRUE,E7*$J$2,0)/100 -> 0.25 | L7: Nedskrevne mål med tidsramme.
C8: 1.1.5 | D8: Virksomheden har en strategi for, hvordan de vil opnå deres CO2e-reduktionsmål. | E8: 10 | F8: TRUE | I8: =IF(F8=TRUE,E8*$J$2,0)/100 -> 0.5 | L8: Nedskreven strategi.
B9: 1.2 | C9: Energiledelse og energiforbrug
C10: 1.2.1 | D10: Virksomheden har udpeget ansvarlige for energiledelse og fastlagt, hvordan ansvaret er organiseret på den pågældende lokation. | E10: 10 | F10: TRUE | G10: =SUMIF(F10:F14,TRUE,E10:E14) -> 35 | H10: 35 | I10: =IF(F10=TRUE,E10*$J$2,0)/100 -> 0.5 | L10: Samlet overblik over energiforbrug fordelt på energikilder.
C11: 1.2.2 | D11: Virksomheden har en politik for at håndtere energiforbrug og energimiks. | E11: 5 | F11: TRUE | I11: =IF(F11=TRUE,E11*$J$2,0)/100 -> 0.25 | L11: Nedskreven politik.
C12: 1.2.3 | D12: Virksomheden har konkrete målsætninger for at øge andelen af vedvarende energi og reducere energiforbruget. | E12: 5 | F12: TRUE | I12: =IF(F12=TRUE,E12*$J$2,0)/100 -> 0.25 | L12: Nedskrevne mål med tidsramme.
C13: 1.2.4 | D13: Virksomheden har en handlingsplan/strategi for, hvordan de vil opnå deres energimål. | E13: 10 | F13: TRUE | I13: =IF(F13=TRUE,E13*$J$2,0)/100 -> 0.5 | L13: Nedskreven strategi.
C14: 1.2.5 | D14: Virksomheden overvåger systematisk og følger op på sit energiforbrug | E14: 5 | F14: TRUE | I14: =IF(F14=TRUE,E14*$J$2,0)/100 -> 0.25
B15: 1.3 | C15: Vedvarende energi
C16: 1.3.1 | D16: Mindst 20% af virksomhedens energiforbrug stammer fra vedvarende energikilder | E16: 2.5 | F16: TRUE | G16: =SUMIF(F16:F19,TRUE,E16:E19) -> 15 | H16: 15 | I16: =IF(F16=TRUE,E16*$J$2,0)/100 -> 0.125
C17: 1.3.2 | D17: Mindst 50% af virksomhedens energiforbrug stammer fra vedvarende energikilder | E17: 2.5 | F17: TRUE | I17: =IF(F17=TRUE,E17*$J$2,0)/100 -> 0.125
C18: 1.3.3 | D18: Hele virksomhedens energiforbrug stammer fra vedvarende energikilder | E18: 5 | F18: TRUE | I18: =IF(F18=TRUE,E18*$J$2,0)/100 -> 0.25
C19: 1.3.4 | D19: Virksomheden kan dokumentere oprindelsen af den energi, som hævdes at være grøn, uanset andel. | E19: 5 | F19: TRUE | I19: =IF(F19=TRUE,E19*$J$2,0)/100 -> 0.25
B20: 1.4 | C20: Energimærke
C21: 1.4.1 | D21: Virksomheden har dokumenteret energimærkningen af størstedelen af sine bygninger. | E21: 5 | F21: TRUE | G21: =SUMIF(F21:F25,TRUE,E21:E25) -> 15 | H21: 15 | I21: =IF(F21=TRUE,E21*$J$2,0)/100 -> 0.25 | L21: Kopi af/link til gyldigt energimærke
C22: 1.4.2 | D22: Størstedelen af virksomhedens bygninger har energimærke B eller bedre. | E22: 2 | F22: TRUE | I22: =IF(F22=TRUE,E22*$J$2,0)/100 -> 0.1 | L22: Kopi af/link til gyldige energimærker og opvarmet etagearealer. Eller kriterie 1.3.3.
C23: 1.4.3 | D23: Størstedelen af virksomhedens bygninger har energimærke A2010 eller bedre. | E23: 2 | F23: TRUE | I23: =IF(F23=TRUE,E23*$J$2,0)/100 -> 0.1 | L23: Kopi af/link til gyldige energimærker og opvarmet etagearealer. Eller kriterie 1.3.4.
C24: 1.4.4 | D24: Størstedelen af virksomhedens bygninger har energimærke A2015 eller bedre. | E24: 2 | F24: TRUE | I24: =IF(F24=TRUE,E24*$J$2,0)/100 -> 0.1 | L24: Kopi af/link til gyldige energimærker og opvarmet etagearealer. Eller kriterie 1.3.5.
C25: 1.4.5 | D25: Størstedelen af virksomhedens bygninger har energimærke A2020. | E25: 4 | F25: TRUE | I25: =IF(F25=TRUE,E25*$J$2,0)/100 -> 0.2 | L25: Kopi af/link til gyldige energimærker og opvarmet etagearealer. Eller kriterie 1.3.3
A26: E2 | B26: Forurening | G26: =SUM(G27:G50) -> 100 | H26: 100 | I26: =G26*J26/100 -> 0 | J26: =Forside!C3/SUM(Forside!C2:C6)*Matrix!K2*100 -> 0
B27: 2.1 | C27: Kortlægning og strategi for forurening
C28: 2.1.1 | D28: Virksomheden har taget stilling til, hvor den har risiko for at bidrage til miljøforurening. | E28: 15 | F28: TRUE | G28: =SUMIF(F28:F31,TRUE,E28:E31) -> 40 | H28: 40 | I28: =IF(F28=TRUE,E28*$J$26,0)/100 -> 0 | L28: Vurdering i form af rapport eller lign.
C29: 2.1.2 | D29: Virksomheden har en politik for forurening. | E29: 10 | F29: TRUE | I29: =IF(F29=TRUE,E29*$J$26,0)/100 -> 0 | L29: Nedskreven politik.
C30: 2.1.3 | D30: Virksomheden har konkrete mål for reduktion af deres forurening. | E30: 5 | F30: TRUE | I30: =IF(F30=TRUE,E30*$J$26,0)/100 -> 0 | L30: Nedskrevne mål med tidsramme.
C31: 2.1.4 | D31: Virksomheden har en handlingsplan/strategi for, hvordan de vil opnå deres mål om mindre forurening. | E31: 10 | F31: TRUE | I31: =IF(F31=TRUE,E31*$J$26,0)/100 -> 0 | L31: Nedskreven strategi.
B32: 2.2 | C32: Luftforurening
C33: 2.2.1 | D33: Virksomheden registrerer og rapporterer sine NOX-, SO2- og partikeludledninger. | E33: 2.5 | F33: TRUE | G33: =SUMIF(F33:F36,TRUE,E33:E36) -> 10 | H33: 10 | I33: =IF(F33=TRUE,E33*$J$26,0)/100 -> 0
C34: 2.2.2 | D34: Virksomheden har målsætninger for reduktion af disse emissioner inden for 3 år. | E34: 2.5 | F34: TRUE | I34: =IF(F34=TRUE,E34*$J$26,0)/100 -> 0
C35: 2.2.3 | D35: Halvdelen af virksomhedens transport er emissionsfri. | E35: 2.5 | F35: TRUE | I35: =IF(F35=TRUE,E35*$J$26,0)/100 -> 0
C36: 2.2.4 | D36: Over 90% af virksomhedens transport er emissionsfri. | E36: 2.5 | F36: TRUE | I36: =IF(F36=TRUE,E36*$J$26,0)/100 -> 0
B37: 2.3 | C37: Vandforurening
C38: 2.3.1 | D38: Virksomheden har dokumenteret spildevandshåndtering, inkl. Rensning. | E38: 5 | F38: TRUE | G38: =SUMIF(F38:F40,TRUE,E38:E40) -> 10 | H38: 10 | I38: =IF(F38=TRUE,E38*$J$26,0)/100 -> 0
C39: 2.3.2 | D39: Halvdelen af virksomhedens spildevand renses før det ledes til kloak/natur. | E39: 2.5 | F39: TRUE | I39: =IF(F39=TRUE,E39*$J$26,0)/100 -> 0
C40: 2.3.3 | D40: Hele virksomhedens spildevand renses før det ledes til kloak/natur. | E40: 2.5 | F40: TRUE | I40: =IF(F40=TRUE,E40*$J$26,0)/100 -> 0
...

Sheet Branchekoder
B1: Branchekode | C1: Titel på branchekode | D1: Beskrivelse
A2: =B2 & " " & C2 -> 01.11.00 Dyrkning af korn (undtagen ris), bælgfrugter og olieholdige frø | B2: 01.11.00 | C2: Dyrkning af korn (undtagen ris), bælgfrugter og olieholdige frø | D2: Branchen omfatter dyrkning af alle former for korn (undtagen ris), herunder pseudo-korn (fx quinoa), bælgfrugter og olieholdige frø.
A3: =B3 & " " & C3 -> 01.12.00 Dyrkning af ris | B3: 01.12.00 | C3: Dyrkning af ris | D3: Branchen omfatter dyrkning af ris.
A4: =B4 & " " & C4 -> 01.13.00 Dyrkning af grøntsager og meloner, rødder og rodknolde | B4: 01.13.00 | C4: Dyrkning af grøntsager og meloner, rødder og rodknolde | D4: Branchen omfatter dyrkning af grøntsager og meloner, rødder og rodknolde, fx agurker, tomater, kartofler, maniok og honningmeloner.
A5: =B5 & " " & C5 | D5: Dyrkning af krydderiplanter og aromaplanter henvises til 01.28.00.
A6: =B6 & " " & C6 -> 01.14.00 Dyrkning af sukkerrør | B6: 01.14.00 | C6: Dyrkning af sukkerrør | D6: Branchen omfatter dyrkning af sukkerrør.
A7: =B7 & " " & C7 | D7: Dyrkning af sukkerroer henvises til 01.13.00.
A8: =B8 & " " & C8 -> 01.15.00 Dyrkning af tobak | B8: 01.15.00 | C8: Dyrkning af tobak | D8: Branchen omfatter dyrkning og den indledende forarbejdning af råtobak.
A9: =B9 & " " & C9 -> 01.16.00 Dyrkning af tekstilplanter | B9: 01.16.00 | C9: Dyrkning af tekstilplanter | D9: Branchen omfatter dyrkning af tekstilplanter, fx bomuld, jute, hør og hamp.
A10: =B10 & " " & C10 -> 01.19.00 Dyrkning af andre etårige afgrøder | B10: 01.19.00 | C10: Dyrkning af andre etårige afgrøder | D10: Branchen omfatter dyrkning af etårige afgrøder, fx foderafgrøder, roefrø og frø fra foderplanter samt dyrkning og fremstilling af blomster, afskårne blomster, blomsterknopper og blomsterfrø.
A11: =B11 & " " & C11 -> 01.21.00 Dyrkning af druer | B11: 01.21.00 | C11: Dyrkning af druer | D11: Branchen omfatter dyrkning af druer, fx druer til presning og spisning.
A12: =B12 & " " & C12
A13: =B13 & " " & C13 | D13: Fremstilling af vin henvises til 11.02.00.
A14: =B14 & " " & C14 -> 01.22.00 Dyrkning af tropiske og subtropiske frugter | B14: 01.22.00 | C14: Dyrkning af tropiske og subtropiske frugter | D14: Branchen omfatter dyrkning af tropiske og subtropiske frugter, fx avocado, ananas, bananer, dadler, figner, mango og papaya.
A15: =B15 & " " & C15 -> 01.23.00 Dyrkning af citrusfrugter | B15: 01.23.00 | C15: Dyrkning af citrusfrugter | D15: Branchen omfatter dyrkning af citrusfrugter, fx grapefrugt, citron, lime og appelsiner.
A16: =B16 & " " & C16 -> 01.24.00 Dyrkning af kernefrugter og stenfrugter | B16: 01.24.00 | C16: Dyrkning af kernefrugter og stenfrugter | D16: Branchen omfatter dyrkning af frugter med sten eller kerner som fx æbler, pærer, kvæder, abrikoser, kirsebær, ferskner, blommer og slåen.
A17: =B17 & " " & C17 -> 01.25.00 Dyrkning af andre træfrugter, bær og nødder | B17: 01.25.00 | C17: Dyrkning af andre træfrugter, bær og nødder | D17: Branchen omfatter dyrkning af andre træfrugter, bær og nødder, fx blåbær, ribs, solbær, stikkelsbær, hindbær, jordbær og kiwifrugter.
A18: =B18 & " " & C18
A19: =B19 & " " & C19 | D19: Branchen omfatter også dyrkning af frugtfrø samt dyrkning af spiselige nødder, bortset fra kokosnødder, som henvises til 01.26.00.
A20: =B20 & " " & C20 -> 01.26.00 Dyrkning af olieholdige frugter | B20: 01.26.00 | C20: Dyrkning af olieholdige frugter | D20: Branchen omfatter dyrkning af olieholdige frugter, fx kokosnødder, oliven og olieplanter.
A21: =B21 & " " & C21
A22: =B22 & " " & C22 | D22: Dyrkning af sojabønner, jordnødder og andre olieholdige frø henvises til 01.11.00.
A23: =B23 & " " & C23 -> 01.27.00 Dyrkning af planter til fremstilling af drikkevarer | B23: 01.27.00 | C23: Dyrkning af planter til fremstilling af drikkevarer | D23: Branchen omfatter dyrkning af planter til fremstilling af drikkevarer, fx kaffe og te.
A24: =B24 & " " & C24 -> 01.28.00 Dyrkning af krydderiplanter, aromaplanter og lægeplanter | B24: 01.28.00 | C24: Dyrkning af krydderiplanter, aromaplanter og lægeplanter | D24: Branchen omfatter dyrkning af krydderiplanter, aromaplanter og lægeplanter som fx peber, chilipeber, muskatnødder, anis, kartemomme, kanel, ingefær, vanilje og humle.
A25: =B25 & " " & C25 -> 01.29.00 Dyrkning af andre flerårige afgrøder | B25: 01.29.00 | C25: Dyrkning af andre flerårige afgrøder | D25: Branchen omfatter dyrkning af andre flerårige afgrøder, fx juletræer, træer til udvinding af træsaft og plantemateriale til brug for fletning. Branchen omfatter også dyrkning af gummitræer til udvinding af latex.
A26: =B26 & " " & C26 -> 01.30.00 Planteformering | B26: 01.30.00 | C26: Planteformering | D26: Branchen omfatter fremstilling af stiklinger, rodskud, sideskud og kimplanter til direkte planteformering eller med henblik på podning til eventuel udplantning.
A27: =B27 & " " & C27 -> 01.41.00 Avl af malkekvæg | B27: 01.41.00 | C27: Avl af malkekvæg | D27: Branchen omfatter opdræt og avl af malkekvæg, fx produktion af råmælk fra køer eller bøfler og produktion af tyresæd af mælkeracer.
A28: =B28 & " " & C28
A29: =B29 & " " & C29 | D29: Forarbejdning af mælk henvises til 10.51.00.
A30: =B30 & " " & C30 -> 01.42.00 Avl af andet kvæg og bøfler | B30: 01.42.00 | C30: Avl af andet kvæg og bøfler | D30: Branchen omfatter opdræt og avl af andet kvæg og bøfler til kødproduktion samt produktion af tyresæd.
A31: =B31 & " " & C31 -> 01.43.00 Avl af heste og dyr af hestefamilien | B31: 01.43.00 | C31: Avl af heste og dyr af hestefamilien | D31: Branchen omfatter opdræt og avl af heste og dyr af hestefamilien, fx æsler, muldyr og mulæsler.
A32: =B32 & " " & C32
A33: =B33 & " " & C33 | D33: Drift af stalde for væddeløbsheste og rideskoler henvises til 93.19.00.
A34: =B34 & " " & C34 -> 01.44.00 Avl af kameler og dyr af kamelfamilien | B34: 01.44.00 | C34: Avl af kameler og dyr af kamelfamilien | D34: Branchen omfatter opdræt og avl af kameler og dyr af kamelfamilien, fx dromedarer.
A35: =B35 & " " & C35 -> 01.45.00 Avl af får og geder | B35: 01.45.00 | C35: Avl af får og geder | D35: Branchen omfatter opdræt og avl af får og geder samt produktion af rå fåremælk og gedemælk samt råuld.
A36: =B36 & " " & C36 -> 01.46.10 Avl af smågrise | B36: 01.46.10 | C36: Avl af smågrise | D36: Branchen omfatter avl af smågrise.
A37: =B37 & " " & C37 -> 01.46.20 Produktion af slagtesvin | B37: 01.46.20 | C37: Produktion af slagtesvin | D37: Branchen omfatter opdræt og avl af slagtesvin.
A38: =B38 & " " & C38 -> 01.47.00 Fjerkræavl | B38: 01.47.00 | C38: Fjerkræavl | D38: Branchen omfatter opdræt og avl af fjerkræ, fx høns, kalkuner, ænder, gæs og perlehøns. Branchen omfatter også ægproduktion og drift af fjerkrærugerier.
A39: =B39 & " " & C39
A40: =B40 & " " & C40 | D40: Produktion af fjer og dun henvises til 10.12.00.
...
